Workbook

Sheet Sheet1
A2: AFG | B2: AUS | C2: BAN | D2: ENG | E2: IND | F2: NZ | G2: PAK | H2: SA
A3: Hashmatullah Shahidi (c) | B3: Steve Smith © | C3: Najmul Hossain Shanto (c) | D3: Jos Buttler (c, wk) | E3: Rohit Sharma (c) | F3: Mitchell Santner (c) | G3: Mohammad Rizwan (c, wk) | H3: Temba Bavuma (c)
A4: Ibrahim Zadran | B4: Alex Carey (wk) | C4: Soumya Sarkar | D4: Jofra Archer | E4: Shubman Gill | F4: Michael Bracewell | G4: Salman Ali Agha (vc) | H4: Tony de Zorzi
A5: Rahmat Shah | B5: Nathan Ellis | C5: Tanzid Hasan | D5: Gus Atkinson | E5: Virat Kohli | F5: Mark Chapman | G5: Shaheen Afridi | H5: Marco Jansen
A6: Sediqullah Atal | B6: Aaron Hardie | C6: Mahmudullah | D6: Jacob Bethell | E6: Shreyas Iyer | F6: Devon Conway (wk) | G6: Abrar Ahmed | H6: Heinrich Klaasen
A7: Azmatullah Omarzai | B7: Travis Head | C7: Jaker Ali (wk) | D7: Harry Brook | E7: KL Rahul | F7: Lockie Ferguson | G7: Faheem Ashraf | H7: Keshav Maharaj
A8: Gulbadin Naib | B8: Josh Inglis (wk) | C8: Mushfiqur Rahim (wk) | D8: Brydon Carse | E8: Rishabh Pant | F8: Matt Henry | G8: Babar Azam | H8: Aiden Markram
A9: Mohammad Nabi | B9: Marnus Labuschagne | C9: Towhid Hridoy | D9: Ben Duckett | E9: Hardik Pandya | F9: Tom Latham (wk) | G9: Kamran Ghulam | H9: David Miller
A10: Ikram Alikhil (wk) | B10: Glenn Maxwell | C10: Mehidy Hasan Miraz | D10: Jamie Overton | E10: Axar Patel | F10: Daryl Mitchell | G10: Mohammad Hasnain | H10: Wiaan Mulder
A11: Rahmanullah Gurbaz (wk) | B11: Matthew Short | C11: Rishad Hossain | D11: Jamie Smith (wk) | E11: Washington Sundar | F11: Glenn Phillips | G11: Usman Khan | H11: Lungi Ngidi
A12: Nangeyalia Kharote | B12: Adam Zampa | C12: Taskin Ahmed | D12: Liam Livingstone | E12: Kuldeep Yadav | F12: Rachin Ravindra | G12: Haris Rauf | H12: Kagiso Rabada
A13: Fareed Ahmad | B13: Sean Abbott | C13: Mustafizur Rahman | D13: Adil Rashid | E13: Harshit Rana | F13: William O'Rourke | G13: Khushdil Shah | H13: Ryan Rickelton
... A17: Rashid Khan | B17: Tanveer Sangha | C17: Nasum Ahmed | D17: Mark Wood | E17: Varun Chakaravarthy | F17: Will Young | G17: Fakhar Zaman | H17: Corbin Bosch
C21: BATTER | D21: BOWLER | E21: WK | F21: AR
C22: Hashmatullah Shahidi (c) | D22: Fareed Ahmad | E22: Ikram Alikhil (wk) | F22: Rahmat Shah
C23: Ibrahim Zadran | D23: Fazalhaq Farooqi | E23: Rahmanullah Gurbaz (wk) | F23: Azmatullah Omarzai
C24: Sediqullah Atal | D24: Naveed Zadran | E24: Alex Carey (wk) | F24: Gulbadin Naib
C25: Steve Smith © | D25: Noor Ahmad | E25: Josh Inglis (wk) | F25: Mohammad Nabi
C26: Travis Head | D26: Nathan Ellis | E26: Jaker Ali (wk) | F26: Nangeyalia Kharote
C27: Matthew Short | D27: Adam Zampa | E27: Mushfiqur Rahim (wk) | F27: Rashid Khan
C28: Jake Fraser-McGurk | D28: Ben Dwarshuis | E28: Parvez Hossain Emon (wk) | F28: Aaron Hardie
C29: Tanzid Hasan | D29: Spencer Johnson | E29: Jos Buttler (c, wk) | F29: Glenn Maxwell
C30: Towhid Hridoy | D30: Tanveer Sangha | E30: Jamie Smith (wk) | F30: Sean Abbott
C31: Harry Brook | D31: Najmul Hossain Shanto (c) | E31: Phil Salt | F31: Soumya Sarkar
C32: Ben Duckett | D32: Taskin Ahmed | E32: KL Rahul | F32: Mahmudullah
... C40: Tayyab Tahir | D40: Kuldeep Yadav | E40: Tristan Stubbs | F40: Liam Livingstone
C41: Fakhar Zaman | D41: Harshit Rana | F41: Hardik Pandya
C42: Temba Bavuma (c) | D42: Mohammed Shami | F42: Axar Patel
C43: Tony de Zorzi | D43: Arshdeep Singh | F43: Washington Sundar
C44: Aiden Markram | D44: Varun Chakaravarthy | F44: Ravindra Jadeja
C45: David Miller | D45: Lockie Ferguson | F45: Mitchell Santner (c)
C46: Rassie van der Dussen | D46: Matt Henry | F46: Michael Bracewell
D47: William O'Rourke | F47: Mark Chapman
D48: Ben Sears | F48: Daryl Mitchell
D49: Shaheen Afridi | F49: Glenn Phillips
D50: Abrar Ahmed | F50: Rachin Ravindra
D51: Mohammad Hasnain | F51: Nathan Smith
D52: Haris Rauf | F52: Salman Ali Agha (vc)
D53: Naseem Shah | F53: Faheem Ashraf
D54: Keshav Maharaj | F54: Kamran Ghulam
...

Sheet Fanz
A1: Player | B1: Team | C1: Price | D1: Point
A2: F Ashraf | B2: PAK | C2: 80 | D2: 10
A3: T Tahir | B3: PAK | C3: 80 | D3: 5
A4: K Shah | B4: PAK | C4: 85 | D4: 247
A5: I Haq | B5: PAK | C5: 85 | D5: 0
A6: U Khan | B6: PAK | C6: 85 | D6: 0
A7: S Shakeel | B7: PAK | C7: 85 | D7: 68
A8: M Hasnain | B8: PAK | C8: 85 | D8: 0
A9: K Ghulam | B9: PAK | C9: 85 | D9: 0
A10: A Salman | B10: PAK | C10: 85 | D10: 118
A11: A Ahmad | B11: PAK | C11: 85 | D11: 85
A12: H Rauf | B12: PAK | C12: 90 | D12: 117
A13: N Shah | B13: PAK | C13: 90 | D13: 94
... A121: J Root | B121: ENG | C121: 95 | D121: 353

Sheet Teams
B1: Anand | C1: Points | D1: Points from Auto-update | E1: Balajee | F1: Points | G1: Points from Auto-update | H1: Devesh | I1: Points | J1: Points from Auto-update | K1: Gogu | L1: Points | M1: Points from Auto-update | N1: Madhavan | O1: Points | P1: Points from Auto-update | Q1: Murthy | R1: Points | S1: Points from Auto-update | T1: Shenoy | U1: Points | V1: Points from Auto-update | W1: Tarang | X1: Points | Y1: Points from Auto-update | Z1: Ankit | AA1: Points | AB1: Points from Auto-update
A2: Batsman | B2: K Williamson | C2: 21 | D2: =INDEX(Fanz!D:D, MATCH(B2, Fanz!A:A, 0)) -> 393 | E2: V Kohli | F2: 29 | G2: =INDEX(Fanz!D:D, MATCH(E2, Fanz!A:A, 0)) -> 443 | H2: T Bavuma | I2: 98 | J2: =INDEX(Fanz!D:D, MATCH(H2, Fanz!A:A, 0)) -> 177 | K2: S Iyer | L2: 19 | M2: =INDEX(Fanz!D:D, MATCH(K2, Fanz!A:A, 0)) -> 330 | N2: B Duckett | O2: 284 | P2: =INDEX(Fanz!D:D, MATCH(N2, Fanz!A:A, 0)) -> 372 | Q2: S Gill | R2: 204 | S2: =INDEX(Fanz!D:D, MATCH(Q2, Fanz!A:A, 0)) -> 297 | T2: T Head | U2: 8 | V2: =INDEX(Fanz!D:D, MATCH(T2, Fanz!A:A, 0)) -> 219 | W2: S Smith | X2: 7 | Y2: =INDEX(Fanz!D:D, MATCH(W2, Fanz!A:A, 0)) -> 126 | Z2: B Azam | AA2: 91 | AB2: =INDEX(Fanz!D:D, MATCH(Z2, Fanz!A:A, 0)) -> 114
A3: WK | B3: D Conway | C3: -1 | D3: =INDEX(Fanz!D:D, MATCH(B3, Fanz!A:A, 0)) -> 36 | E3: J Inglis | F3: 271 | G3: =INDEX(Fanz!D:D, MATCH(E3, Fanz!A:A, 0)) -> 312 | H3: H Klaasen | I3: 0 | J3: =INDEX(Fanz!D:D, MATCH(H3, Fanz!A:A, 0)) -> 159 | K3: M Rahim | L3: -10 | M3: =INDEX(Fanz!D:D, MATCH(K3, Fanz!A:A, 0)) -> 2 | N3: KL Rahul | O3: 73 | P3: =INDEX(Fanz!D:D, MATCH(N3, Fanz!A:A, 0)) -> 275 | Q3: A Carey | R3: 155 | S3: =INDEX(Fanz!D:D, MATCH(Q3, Fanz!A:A, 0)) -> 287 | T3: R Gurbaz | U3: 22 | V3: =INDEX(Fanz!D:D, MATCH(T3, Fanz!A:A, 0)) -> 18 | W3: T Latham | X3: 258 | Y3: =INDEX(Fanz!D:D, MATCH(W3, Fanz!A:A, 0)) -> 371
A4: AR | B4: M Jansen | C4: 50 | D4: =INDEX(Fanz!D:D, MATCH(B4, Fanz!A:A, 0)) -> 223 | E4: R Jadeja | F4: 15 | G4: =INDEX(Fanz!D:D, MATCH(E4, Fanz!A:A, 0)) -> 246 | H4: A Patel | I4: 95 | J4: =INDEX(Fanz!D:D, MATCH(H4, Fanz!A:A, 0)) -> 386 | K4: G Maxwell | L4: 120 | M4: =INDEX(Fanz!D:D, MATCH(K4, Fanz!A:A, 0)) -> 212 | N4: G Phillips | O4: 162 | P4: =INDEX(Fanz!D:D, MATCH(N4, Fanz!A:A, 0)) -> 428 | Q4: D Mitchell | R4: 0 | S4: =INDEX(Fanz!D:D, MATCH(Q4, Fanz!A:A, 0)) -> 165 | T4: L Livingstone | U4: 49 | V4: =INDEX(Fanz!D:D, MATCH(T4, Fanz!A:A, 0)) -> 134 | W4: H Pandya | X4: 20 | Y4: =INDEX(Fanz!D:D, MATCH(W4, Fanz!A:A, 0)) -> 358
A5: Bowler | B5: S Johnson | C5: 5 | D5: =INDEX(Fanz!D:D, MATCH(B5, Fanz!A:A, 0)) -> 90 | E5: M Henry | F5: 100 | G5: =INDEX(Fanz!D:D, MATCH(E5, Fanz!A:A, 0)) -> 382 | H5: A Ahmad | I5: 40 | J5: =INDEX(Fanz!D:D, MATCH(H5, Fanz!A:A, 0)) -> 85 | K5: N Shah | L5: 73 | M5: =INDEX(Fanz!D:D, MATCH(K5, Fanz!A:A, 0)) -> 94 | N5: K Maharaj | O5: 50 | P5: =INDEX(Fanz!D:D, MATCH(N5, Fanz!A:A, 0)) -> 156 | Q5: W O Rourke | R5: 100 | S5: =INDEX(Fanz!D:D, MATCH(Q5, Fanz!A:A, 0)) -> 251 | T5: M Shami | U5: 185 | V5: =INDEX(Fanz!D:D, MATCH(T5, Fanz!A:A, 0)) -> 355 | W5: K Yadav | X5: 15 | Y5: =INDEX(Fanz!D:D, MATCH(W5, Fanz!A:A, 0)) -> 286 | Z5: H Rauf | AA5: 99 | AB5: =INDEX(Fanz!D:D, MATCH(Z5, Fanz!A:A, 0)) -> 117
A6: Floaters | B6: I Zadran | C6: 9 | D6: =INDEX(Fanz!D:D, MATCH(B6, Fanz!A:A, 0)) -> 361 | E6: R Sharma | F6: 75 | G6: =INDEX(Fanz!D:D, MATCH(E6, Fanz!A:A, 0)) -> 387 | H6: J Buttler | I6: 70 | J6: =INDEX(Fanz!D:D, MATCH(H6, Fanz!A:A, 0)) -> 129 | K6: R Ravindra | L6: 0 | M6: =INDEX(Fanz!D:D, MATCH(K6, Fanz!A:A, 0)) -> 686 | N6: A Salman | O6: 109 | P6: =INDEX(Fanz!D:D, MATCH(N6, Fanz!A:A, 0)) -> 118 | Q6: M Hasan | R6: 27 | S6: =INDEX(Fanz!D:D, MATCH(Q6, Fanz!A:A, 0)) -> 57 | T6: A Markram | U6: 129 | V6: =INDEX(Fanz!D:D, MATCH(T6, Fanz!A:A, 0)) -> 216 | W6: R Rickelton | X6: 227 | Y6: =INDEX(Fanz!D:D, MATCH(W6, Fanz!A:A, 0)) -> 319
B7: H shahidi | C7: 0 | D7: =INDEX(Fanz!D:D, MATCH(B7, Fanz!A:A, 0)) -> 33 | E7: M Bracewell | F7: 75 | G7: =INDEX(Fanz!D:D, MATCH(E7, Fanz!A:A, 0)) -> 549 | H7: L ngidi | I7: 65 | J7: =INDEX(Fanz!D:D, MATCH(H7, Fanz!A:A, 0)) -> 221 | K7: Fakhar Zaman | L7: 27 | M7: 27 | N7: N Ahmed | O7: 0 | P7: =INDEX(Fanz!D:D, MATCH(N7, Fanz!A:A, 0)) -> 0 | Q7: R Khan | R7: 39 | S7: =INDEX(Fanz!D:D, MATCH(Q7, Fanz!A:A, 0)) -> 113 | T7: R v d Dussen | U7: 108 | V7: =INDEX(Fanz!D:D, MATCH(T7, Fanz!A:A, 0)) -> 354 | W7: P salt | X7: 17 | Y7: =INDEX(Fanz!D:D, MATCH(W7, Fanz!A:A, 0)) -> 45
B8: N Ahmad | C8: 26 | D8: =INDEX(Fanz!D:D, MATCH(B8, Fanz!A:A, 0)) -> 42 | E8: N Smith | F8: 25 | G8: =INDEX(Fanz!D:D, MATCH(E8, Fanz!A:A, 0)) -> 25 | H8: S Shakeel | I8: -14 | J8: =INDEX(Fanz!D:D, MATCH(H8, Fanz!A:A, 0)) -> 68 | K8: Mahmudullah | L8: 0 | M8: =INDEX(Fanz!D:D, MATCH(K8, Fanz!A:A, 0)) -> 14 | N8: J Overton | O8: 0 | P8: =INDEX(Fanz!D:D, MATCH(N8, Fanz!A:A, 0)) -> 91 | Q8: A Rashid | R8: 51 | S8: =INDEX(Fanz!D:D, MATCH(Q8, Fanz!A:A, 0)) -> 133 | T8: T tahir | U8: 1 | V8: =INDEX(Fanz!D:D, MATCH(T8, Fanz!A:A, 0)) -> 5 | W8: M Santner | X8: 95 | Y8: =INDEX(Fanz!D:D, MATCH(W8, Fanz!A:A, 0)) -> 430
B9: N Kharote | C9: 0 | D9: =INDEX(Fanz!D:D, MATCH(B9, Fanz!A:A, 0)) -> 0 | E9: W Sundar | F9: 0 | G9: =INDEX(Fanz!D:D, MATCH(E9, Fanz!A:A, 0)) -> 0 | H9: R Shah | I9: 163 | J9: =INDEX(Fanz!D:D, MATCH(H9, Fanz!A:A, 0)) -> 176 | K9: G Naib | L9: 7 | M9: =INDEX(Fanz!D:D, MATCH(K9, Fanz!A:A, 0)) -> 47 | N9: V Chakravarthy | O9: 0 | P9: =INDEX(Fanz!D:D, MATCH(N9, Fanz!A:A, 0)) -> 365 | Q9: S Afridi | R9: 34 | S9: =INDEX(Fanz!D:D, MATCH(Q9, Fanz!A:A, 0)) -> 84 | T9: M Labuschagne | U9: 152 | V9: =INDEX(Fanz!D:D, MATCH(T9, Fanz!A:A, 0)) -> 200 | W9: J Duffy | X9: 0 | Y9: =INDEX(Fanz!D:D, MATCH(W9, Fanz!A:A, 0)) -> 0
B10: N Zadran | C10: 0 | D10: =INDEX(Fanz!D:D, MATCH(B10, Fanz!A:A, 0)) -> 0 | E10: N Ellis | F10: 30 | G10: =INDEX(Fanz!D:D, MATCH(E10, Fanz!A:A, 0)) -> 150 | H10: Tanzim Hasan | I10: -5 | J10: =INDEX(Fanz!D:D, MATCH(H10, Fanz!A:A, 0)) -> -5 | K10: A Zampa | L10: 65 | M10: =INDEX(Fanz!D:D, MATCH(K10, Fanz!A:A, 0)) -> 202 | N10: H Rana | O10: 105 | P10: =INDEX(Fanz!D:D, MATCH(N10, Fanz!A:A, 0)) -> 150 | Q10: T Shamsi | R10: 0 | S10: =INDEX(Fanz!D:D, MATCH(Q10, Fanz!A:A, 0)) -> 0 | T10: P Hossain | U10: 0 | V10: =INDEX(Fanz!D:D, MATCH(T10, Fanz!A:A, 0)) -> 10 | W10: H Brook | X10: 3 | Y10: =INDEX(Fanz!D:D, MATCH(W10, Fanz!A:A, 0)) -> 64
B11: F Ahmad | C11: 0 | D11: =INDEX(Fanz!D:D, MATCH(B11, Fanz!A:A, 0)) -> 0 | E11: Lockie Ferguson | F11: 0 | G11: 0 | H11: S Sarkar | I11: 0 | J11: =INDEX(Fanz!D:D, MATCH(H11, Fanz!A:A, 0)) -> 0 | K11: M Wood | L11: 30 | M11: =INDEX(Fanz!D:D, MATCH(K11, Fanz!A:A, 0)) -> 37 | N11: S Mahmood | O11: 0 | P11: =INDEX(Fanz!D:D, MATCH(N11, Fanz!A:A, 0)) -> 20 | Q11: F Farooqi | R11: 30 | S11: =INDEX(Fanz!D:D, MATCH(Q11, Fanz!A:A, 0)) -> 50 | T11: J Ali | U11: 81 | V11: =INDEX(Fanz!D:D, MATCH(T11, Fanz!A:A, 0)) -> 127 | W11: B Dwarshuis | X11: 95 | Y11: =INDEX(Fanz!D:D, MATCH(W11, Fanz!A:A, 0)) -> 251
B12: T Sangha | C12: 0 | D12: =INDEX(Fanz!D:D, MATCH(B12, Fanz!A:A, 0)) -> 6 | E12: N Hossain | F12: 0 | G12: =INDEX(Fanz!D:D, MATCH(E12, Fanz!A:A, 0)) -> 115 | H12: W Young | I12: 186 | J12: =INDEX(Fanz!D:D, MATCH(H12, Fanz!A:A, 0)) -> 250 | K12: M hasnain | L12: 0 | M12: =INDEX(Fanz!D:D, MATCH(K12, Fanz!A:A, 0)) -> 0 | N12: M Rahman | O12: 30 | P12: =INDEX(Fanz!D:D, MATCH(N12, Fanz!A:A, 0)) -> 73 | Q12: J Root | R12: 91 | S12: =INDEX(Fanz!D:D, MATCH(Q12, Fanz!A:A, 0)) -> 353 | T12: T Banton | U12: 0 | V12: =INDEX(Fanz!D:D, MATCH(T12, Fanz!A:A, 0)) -> 10
B13: Tanzid Hasan | C13: 53 | D13: =INDEX(Fanz!D:D, MATCH(B13, Fanz!A:A, 0)) -> 109 | E13: M Short | F13: 116 | G13: =INDEX(Fanz!D:D, MATCH(E13, Fanz!A:A, 0)) -> 30 | H13: Akif Javed | I13: 0 | J13: 0 | K13: R Pant | L13: 0 | M13: =INDEX(Fanz!D:D, MATCH(K13, Fanz!A:A, 0)) -> 0 | N13: T Hridoy | O13: 152 | P13: =INDEX(Fanz!D:D, MATCH(N13, Fanz!A:A, 0)) -> 139 | Q13: T de Zorzi | R13: 15 | S13: =INDEX(Fanz!D:D, MATCH(Q13, Fanz!A:A, 0)) -> 15 | T13: M Nabi | U13: 58 | V13: =INDEX(Fanz!D:D, MATCH(T13, Fanz!A:A, 0)) -> 268
B14: T Ahmed | C14: 43 | D14: =INDEX(Fanz!D:D, MATCH(B14, Fanz!A:A, 0)) -> 100 | E14: J F McGurk | F14: 0 | G14: =INDEX(Fanz!D:D, MATCH(E14, Fanz!A:A, 0)) -> 0 | H14: I Alikhil | I14: 0 | J14: =INDEX(Fanz!D:D, MATCH(H14, Fanz!A:A, 0)) -> 0 | K14: J Smith | L14: 21 | M14: =INDEX(Fanz!D:D, MATCH(K14, Fanz!A:A, 0)) -> 24 | N14: M Rizwan | O14: 13 | P14: =INDEX(Fanz!D:D, MATCH(N14, Fanz!A:A, 0)) -> 60 | Q14: S Atal | R14: 15 | S14: =INDEX(Fanz!D:D, MATCH(Q14, Fanz!A:A, 0)) -> 153 | T14: M Chapman | U14: 0 | V14: =INDEX(Fanz!D:D, MATCH(T14, Fanz!A:A, 0)) -> 0
B15: D Miller | C15: 6 | D15: =INDEX(Fanz!D:D, MATCH(B15, Fanz!A:A, 0)) -> 228 | K15: U Khan | L15: 0 | M15: =INDEX(Fanz!D:D, MATCH(K15, Fanz!A:A, 0)) -> 0 | N15: T Stubbs | O15: 0 | P15: =INDEX(Fanz!D:D, MATCH(N15, Fanz!A:A, 0)) -> -10 | Q15: F Ashraf | R15: 10 | S15: =INDEX(Fanz!D:D, MATCH(Q15, Fanz!A:A, 0)) -> 10 | T15: W Mulder | U15: 94 | V15: =INDEX(Fanz!D:D, MATCH(T15, Fanz!A:A, 0)) -> 244
B16: G Atkinson | C16: 0 | D16: =INDEX(Fanz!D:D, MATCH(B16, Fanz!A:A, 0)) -> 0 | T16: A Hardie | U16: 0 | V16: =INDEX(Fanz!D:D, MATCH(T16, Fanz!A:A, 0)) -> 0
T17: A Omarzai | U17: 49 | V17: =INDEX(Fanz!D:D, MATCH(T17, Fanz!A:A, 0)) -> 486
T18: K Shah | U18: 154 | V18: =INDEX(Fanz!D:D, MATCH(T18, Fanz!A:A, 0)) -> 247
T19: B Carse | U19: 23 | V19: 23
T20: S Abbott | U20: 0 | V20: =INDEX(Fanz!D:D, MATCH(T20, Fanz!A:A, 0)) -> 0
T21: K Ghulam | U21: 0 | V21: =INDEX(Fanz!D:D, MATCH(T21, Fanz!A:A, 0)) -> 0
T22: C Bosch | U22: 0 | V22: =INDEX(Fanz!D:D, MATCH(T22, Fanz!A:A, 0)) -> 0
T23: R Hossain | U23: 130 | V23: =INDEX(Fanz!D:D, MATCH(T23, Fanz!A:A, 0)) -> 215
T24: J Archer | U24: 110 | V24: =INDEX(Fanz!D:D, MATCH(T24, Fanz!A:A, 0)) -> 321
T25: N Rana | U25: 0 | V25: =INDEX(Fanz!D:D, MATCH(T25, Fanz!A:A, 0)) -> 40
T26: K Rabada | U26: 125 | V26: =INDEX(Fanz!D:D, MATCH(T26, Fanz!A:A, 0)) -> 260
T27: A Singh | U27: 0 | V27: =INDEX(Fanz!D:D, MATCH(T27, Fanz!A:A, 0)) -> 0
A28: Total | C28: {=SUM(C2:C5)+SUM(LARGE(C6:C27, {1,2,3,4,5,6,7}))} -> 212 | D28: {=SUM(D2:D5)+SUM(LARGE(D6:D27, {1,2,3,4,5,6,7}))} -> 1621 | F28: {=SUM(F2:F5)+SUM(LARGE(F6:F27, {1,2,3,4,5,6,7}))} -> 736 | G28: {=SUM(G2:G5)+SUM(LARGE(G6:G27, {1,2,3,4,5,6,7}))} -> 2639 | I28: {=SUM(I2:I5)+SUM(LARGE(I6:I27, {1,2,3,4,5,6,7}))} -> 717 | J28: {=SUM(J2:J5)+SUM(LARGE(J6:J27, {1,2,3,4,5,6,7}))} -> 1651 | L28: {=SUM(L2:L5)+SUM(LARGE(L6:L27, {1,2,3,4,5,6,7}))} -> 352 | M28: {=SUM(M2:M5)+SUM(LARGE(M6:M27, {1,2,3,4,5,6,7}))} -> 1675 | O28: {=SUM(O2:O5)+SUM(LARGE(O6:O27, {1,2,3,4,5,6,7}))} -> 978 | P28: {=SUM(P2:P5)+SUM(LARGE(P6:P27, {1,2,3,4,5,6,7}))} -> 2227 | R28: {=SUM(R2:R5)+SUM(LARGE(R6:R27, {1,2,3,4,5,6,7}))} -> 746 | S28: {=SUM(S2:S5)+SUM(LARGE(S6:S27, {1,2,3,4,5,6,7}))} -> 1943 | U28: {=SUM(U2:U5)+SUM(LARGE(U6:U27, {1,2,3,4,5,6,7}))} -> 1172 | V28: {=SUM(V2:V5)+SUM(LARGE(V6:V27, {1,2,3,4,5,6,7}))} -> 2906 | X28: {=SUM(X2:X5)+SUM(LARGE(X6:X11, {1,2,3,4,5,6}))} -> 737 | Y28: {=SUM(Y2:Y5)+SUM(LARGE(Y6:Y11, {1,2,3,4,5,6}))} -> 2250 | AA28: =SUM(AA2:AA5) -> 190 | AB28: =SUM(AB2:AB5) -> 231
A29: Fixed Points | C29: =SUM(C2:C5) -> 75 | D29: =SUM(D2:D5) -> 742 | F29: =SUM(F2:F5) -> 415 | G29: =SUM(G2:G5) -> 1383 | I29: =SUM(I2:I5) -> 233 | J29: =SUM(J2:J5) -> 807 | L29: =SUM(L2:L5) -> 202 | M29: =SUM(M2:M5) -> 638 | O29: =SUM(O2:O5) -> 569 | P29: =SUM(P2:P5) -> 1231 | R29: =SUM(R2:R5) -> 459 | S29: =SUM(S2:S5) -> 1000 | U29: =SUM(U2:U5) -> 264 | V29: =SUM(V2:V5) -> 726 | X29: =SUM(X2:X5) -> 300 | Y29: =SUM(Y2:Y5) -> 1141 | AA29: =SUM(AA2:AA5) -> 190 | AB29: =SUM(AB2:AB5) -> 231
A30: Floater points | C30: {=SUM(LARGE(C6:C27, {1,2,3,4,5,6,7}))} -> 137 | D30: {=SUM(LARGE(D6:D27, {1,2,3,4,5,6,7}))} -> 879 | F30: {=SUM(LARGE(F6:F27, {1,2,3,4,5,6,7}))} -> 321 | G30: {=SUM(LARGE(G6:G27, {1,2,3,4,5,6,7}))} -> 1256 | I30: {=SUM(LARGE(I6:I27, {1,2,3,4,5,6,7}))} -> 484 | J30: {=SUM(LARGE(J6:J27, {1,2,3,4,5,6,7}))} -> 844 | L30: {=SUM(LARGE(L6:L27, {1,2,3,4,5,6,7}))} -> 150 | M30: {=SUM(LARGE(M6:M27, {1,2,3,4,5,6,7}))} -> 1037 | O30: {=SUM(LARGE(O6:O27, {1,2,3,4,5,6,7}))} -> 409 | P30: {=SUM(LARGE(P6:P27, {1,2,3,4,5,6,7}))} -> 996 | R30: {=SUM(LARGE(R6:R27, {1,2,3,4,5,6,7}))} -> 287 | S30: {=SUM(LARGE(S6:S27, {1,2,3,4,5,6,7}))} -> 943 | U30: {=SUM(LARGE(U6:U27, {1,2,3,4,5,6,7}))} -> 908 | V30: {=SUM(LARGE(V6:V27, {1,2,3,4,5,6,7}))} -> 2180 | X30: {=SUM(LARGE(X6:X11, {1,2,3,4,5,6}))} -> 437 | Y30: {=SUM(LARGE(Y6:Y11, {1,2,3,4,5,6}))} -> 1109 | AA30: 0 | AB30: 0
A32: Anand | B32: =D28 -> 1621 | E32: =INDEX(Fanz!A2:A121, MATCH(LARGE(Fanz!$D$2:$D$121,1), Fanz!$D$2:$D$121, 0)) -> R Ravindra | G32: =LARGE(Fanz!D$2:D$121,1) -> 686
A33: Balajee | B33: =G28 -> 2639 | E33: =INDEX(Fanz!$A$2:$A$121, MATCH(LARGE(Fanz!$D$2:$D$121,2), Fanz!$D$2:$D$121, 0)) -> M Bracewell | G33: =LARGE(Fanz!D$2:D$121,2) -> 549
A34: Devesh | B34: =J28 -> 1651 | E34: =INDEX(Fanz!$A$2:$A$121, MATCH(LARGE(Fanz!$D$2:$D$121,3), Fanz!$D$2:$D$121, 0)) -> A Omarzai | G34: =LARGE(Fanz!D$2:D$121,3) -> 486
A35: Gogu | B35: =M28 -> 1675 | E35: =INDEX(Fanz!$A$2:$A$121, MATCH(LARGE(Fanz!$D$2:$D$121,4), Fanz!$D$2:$D$121, 0)) -> V Kohli | G35: =LARGE(Fanz!D$2:D$121,4) -> 443
A36: Maddy | B36: =P28 -> 2227 | E36: =INDEX(Fanz!$A$2:$A$121, MATCH(LARGE(Fanz!$D$2:$D$121,5), Fanz!$D$2:$D$121, 0)) -> M Santner | G36: =LARGE(Fanz!D$2:D$121,5) -> 430
A37: Murthy | B37: =S28 -> 1943 | E37: =INDEX(Fanz!$A$2:$A$121, MATCH(LARGE(Fanz!$D$2:$D$121,6), Fanz!$D$2:$D$121, 0)) -> G Phillips | G37: =LARGE(Fanz!D$2:D$121,6) -> 428
A38: Shenoy | B38: =V28 -> 2906 | E38: =INDEX(Fanz!$A$2:$A$121, MATCH(LARGE(Fanz!$D$2:$D$121,7), Fanz!$D$2:$D$121, 0)) -> K Williamson | G38: =LARGE(Fanz!D$2:D$121,7) -> 393
A39: Tarang | B39: =Y28 -> 2250 | E39: =INDEX(Fanz!$A$2:$A$121, MATCH(LARGE(Fanz!$D$2:$D$121,8), Fanz!$D$2:$D$121, 0)) -> R Sharma | G39: =LARGE(Fanz!D$2:D$121,8) -> 387 | J39: Shenoy | K39: =2906-355-268+216+215 -> 2714
A40: Ankit | B40: =AB28 -> 231 | E40: =INDEX(Fanz!$A$2:$A$121, MATCH(LARGE(Fanz!$D$2:$D$121,9), Fanz!$D$2:$D$121, 0)) -> A Patel | G40: =LARGE(Fanz!D$2:D$121,9) -> 386 | J40: Murthy | K40: =1943-133+223+549-84 -> 2498
E41: =INDEX(Fanz!$A$2:$A$121, MATCH(LARGE(Fanz!$D$2:$D$121,10), Fanz!$D$2:$D$121, 0)) -> M Henry | G41: =LARGE(Fanz!D$2:D$121,10) -> 382 | J41: Gogu | K41: =1675-2-37+355+268 -> 2259
...

Sheet Squads
B1: Anand | C1: Devesh | D1: Balajee
B2: Kharote | C2: Temba Bavuma | D2: Rohit Sharma
B3: Noor Ahmad | C3: Jos Butler | D3: Virat Kohli
B4: Adil Rashid | C4: Heinrich Klassen | D4: Ravindra Jadeja
B5: David Miller | C5: Axar Patel | D5: Matt Henry
B6: Hashmatullah Shahidi (c) | C6: Saud Shakeel
B7: Tony de Zorzi | C7: Soumya Sarkar | H7: Josh Inglis (wk)
B8: Ibrahim Zadran
B9: Naveed
B10: Spencer | D10: Ravindra Jadeja
B11: Axar | D11: Michael Bracewell
B12: Adil Rashid | D12: Nathan Smith
B13: Fareed | D13: Washington Sundar
B14: Tanveer Sangha
B15: Conway
B16: Tanzid | D16: Nathan Ellis
D17: Lockie Ferguson
D18: Najmul Hossain Shanto (c)
D19: Matt Henry
D22: Rohit Sharma (c)
D23: Virat Kohli
D24: Matthew Short
D25: Jake Fraser-McGurk

Sheet AR
A1: Lot | B1: Random | C1: Team | D1: Player | E1: Sold to | F1: Price (cr)
A2: 1 | B2: 0.017629146 | C2: AFG | D2: Gulbadin Naib | E2: Gogu | F2: 6.5
B3: 0.074982489 | C3: NZ | D3: Mark Chapman | E3: Shenoy | F3: 1
B4: 0.10413719 | C4: AFG | D4: Mohammad Nabi | E4: Gogu | F4: 7
B5: 0.11831697 | C5: RSA | D5: Wiaan Mulder | E5: Shenoy | F5: 1
B6: 0.14221221 | C6: BAN | D6: Soumya Sarkar | E6: Devesh | F6: 8
B7: 0.15403488 | C7: NZ | D7: Rachin Ravindra | E7: Gogu | F7: 2
B8: 0.17650094 | C8: AUS | D8: Aaron Hardie | E8: Shenoy | F8: 3.4
B9: 0.19230558 | C9: PAK | D9: Saud Shakeel | E9: Devesh | F9: 5
B10: 0.26146846 | C10: RSA | D10: Marco Jansen | E10: Murthy | F10: 9
B11: 0.27590889 | C11: AFG | D11: Azmatullah Omarzai | E11: Shenoy | F11: 6.5
A12: 2 | B12: 0.28259758 | C12: PAK | D12: Khushdil Shah | E12: Shenoy | F12: 3
B13: 0.31237277 | C13: IND | D13: Ravindra Jadeja | E13: Balajee | F13: 15.5
B14: 0.31247833 | C14: NZ | D14: Michael Bracewell | E14: Murthy | F14: 8.5
B15: 0.3143122 | C15: ENG | D15: Liam Livingstone | E15: Shenoy | F15: 6.5
B16: 0.34050763 | C16: NZ | D16: Mitchell Santner (c) | E16: Tarang | F16: 12.5
B17: 0.347247 | C17: AFG | D17: Nangeyalia Kharote | E17: Anand | F17: 1.6
B18: 0.3529117 | C18: BAN | D18: Mehidy Hasan Miraz | E18: Murthy | F18: 6
B19: 0.41746623 | C19: ENG | D19: Brydon Carse | E19: Shenoy | F19: 1.5
B20: 0.42064047 | C20: PAK | D20: Salman Ali Agha (vc) | E20: Maddy | F20: 11
B21: 0.46131078 | C21: BAN | D21: Tanzim Hasan Sakib | E21: Devesh | F21: 1.5
A22: 3 | B22: 0.59165247
B23: 0.59457898 | C23: AUS | D23: Sean Abbott | E23: Shenoy | F23: 5
B24: 0.59894173 | C24: BAN | D24: Nasum Ahmed | E24: Maddy | F24: 1.5
B25: 0.60887645 | C25: NZ | D25: Glenn Phillips | E25: Maddy | F25: 15.5
B26: 0.61301383 | C26: PAK | D26: Kamran Ghulam | E26: Shenoy | F26: 1
B27: 0.65700938 | C27: AFG | D27: Rahmat Shah | E27: Devesh | F27: 4.5
B28: 0.66009413 | C28: ENG | D28: Jamie Overton | E28: Maddy | F28: 6
B29: 0.69520706 | C29: BAN | D29: Mahmudullah | E29: Gogu | F29: 6
B30: 0.75162987 | C30: AUS | D30: Glenn Maxwell | E30: Gogu | F30: 12.5
B31: 0.78625891 | C31: NZ | D31: Nathan Smith | E31: Balajee | F31: 2.5
A32: 4 | B32: 0.79291734 | C32: NZ | D32: Daryl Mitchell | E32: Murthy | F32: 10.5
B33: 0.82752454 | C33: RSA | D33: Corbin Bosch | E33: Shenoy | F33: 1
B34: 0.84798631 | C34: AFG | D34: Rashid Khan | E34: Murthy | F34: 9.5
B35: 0.90450801 | C35: IND | D35: Washington Sundar | E35: Balajee | F35: 3
B36: 0.94880559 | C36: IND | D36: Hardik Pandya | E36: Tarang | F36: 13
B37: 0.96246942 | C37: BAN | D37: Rishad Hossain | E37: Shenoy | F37: 2
B38: 0.97550024 | C38: IND | D38: Axar Patel | E38: Anand | F38: 21
B39: 0.99110476 | C39: PAK | D39: Faheem Ashraf | E39: Murthy | F39: 1

Sheet Bowlers
A1: Lot | B1: Random | C1: Team | D1: Player | E1: Sold to | F1: Price (cr)
A2: 1 | B2: 0.028981187 | C2: ENG | D2: Jofra Archer | E2: Shenoy | F2: 5.5
B3: 0.03535897 | C3: BAN | D3: Taskin Ahmed | E3: Devesh | F3: 6.5
B4: 0.039359843 | C4: PAK | D4: Mohammad Hasnain | E4: Gogu | F4: 2.5
B5: 0.19300741 | C5: AFG | D5: Fazalhaq Farooqi | E5: Murthy | F5: 6.5
B6: 0.19756952 | C6: BAN | D6: Mustafizur Rahman | E6: Maddy | F6: 4.5
B7: 0.20638566 | C7: NZ | D7: William O'Rourke | E7: Murthy | F7: 7
B8: 0.20686142 | C8: BAN | D8: Nahid Rana | E8: Shenoy | F8: 1
B9: 0.21086602 | C9: RSA | D9: Lungi Ngidi | E9: Devesh | F9: 8
B10: 0.26386524 | C10: PAK | D10: Akif Javed | E10: Devesh | F10: 1.5
A11: 2 | B11: 0.26551441 | C11: AFG | D11: Naveed Zadran | E11: Anand | F11: 1.5
B12: 0.29026911 | C12: AUS | D12: Nathan Ellis | E12: Balajee | F12: 4
B13: 0.2911331 | C13: AUS | D13: Adam Zampa | E13: Gogu | F13: 11
B14: 0.33254391 | C14: NZ | D14: Lockie Ferguson | E14: Balajee | F14: 1
B15: 0.36783706 | C15: RSA | D15: Keshav Maharaj | E15: Maddy | F15: 9.5
B16: 0.4017189 | C16: AFG | D16: Noor Ahmad | E16: Anand | F16: 7
B17: 0.4437268 | C17: IND | D17: Mohammed Shami | E17: Gogu | F17: 9
B18: 0.46541897 | C18: RSA | D18: Tabraiz Shamsi | E18: Balajee | F18: 5
B19: 0.48908258 | C19: ENG | D19: Adil Rashid | E19: Anand | F19: 13.5
A20: 3 | B20: 0.5410694 | C20: BAN | D20: Najmul Hossain Shanto (c) | E20: Balajee | F20: 4.5
B21: 0.56072804 | C21: NZ | D21: Jacob Duffy | E21: Tarang | F21: 7
B22: 0.61110853 | C22: ENG | D22: Gus Atkinson | E22: Murthy | F22: 1.5
B23: 0.65433075 | C23: AUS | D23: Spencer Johnson | E23: Anand | F23: 8.5
B24: 0.66753356 | C24: PAK | D24: Abrar Ahmed | E24: Devesh | F24: 9
B25: 0.67940011 | C25: IND | D25: Kuldeep Yadav | E25: Tarang | F25: 7.5
B26: 0.69662362 | C26: AFG | D26: Fareed Ahmad | E26: Anand | F26: 1
B27: 0.70201038 | C27: IND | D27: Varun Chakaravarthy | E27: Maddy | F27: 6
B28: 0.74196274 | C28: PAK | D28: Shaheen Afridi | E28: Balajee | F28: 8.5
A29: 4 | B29: 0.75788728 | C29: IND | D29: Harshit Rana | E29: Maddy | F29: 7.5
B30: 0.79453274 | C30: RSA | D30: Kagiso Rabada | E30: Shenoy | F30: 4.5
B31: 0.84840325 | C31: ENG | D31: Saqib Mahmood | E31: Maddy | F31: 2
B32: 0.87105213 | C32: AUS | D32: Tanveer Sangha | E32: Anand | F32: 1.5
B33: 0.88399546 | C33: AUS | D33: Ben Dwarshuis | E33: Tarang | F33: 3
B34: 0.9326156 | C34: NZ | D34: Matt Henry | E34: Balajee | F34: 10
B35: 0.95026913 | C35: ENG | D35: Mark Wood | E35: Shenoy | F35: 3.5
B36: 0.96005107 | C36: IND | D36: Arshdeep Singh | E36: Shenoy | F36: 13
B37: 0.97822341 | C37: PAK | D37: Naseem Shah | E37: Gogu | F37: 9.5

Sheet Batsman
A1: Lot | B1: Random | C1: Team | D1: Player | E1: Sold to | F1: Price (cr) | I1: Anand | J1: Balajee | K1: Devesh | L1: Gogu | M1: Maddy | N1: Murthy | O1: Shenoy | P1: Tarang
A2: 1 | B2: 0.011411008 | C2: RSA | D2: Aiden Markram | E2: Shenoy | F2: 9.5 | H2: Initial Budget | I2: 100 | J2: 100 | K2: 100 | L2: 100 | M2: 100 | N2: 100 | O2: 100 | P2: 100
B3: 0.022413735 | C3: PAK | D3: Fakhar Zaman | E3: Gogu | F3: 11.5 | I3: 1.5 | J3: 11.1 | K3: 15.2 | L3: 6.5 | M3: 15 | N3: 15.2 | O3: 7.1 | P3: 15
B4: 0.023312333 | C4: RSA | D4: Rassie van der Dussen | E4: Shenoy | F4: 4 | I4: 7 | J4: 5 | K4: 8 | L4: 7 | M4: 4.5 | N4: 9 | O4: 1 | P4: 11
B5: 0.036381758 | C5: ENG | D5: Ben Duckett | E5: Maddy | F5: 6.5 | I5: 13.5 | J5: 15.5 | K5: 5 | L5: 2 | M5: 6.5 | N5: 6.5 | O5: 1 | P5: 10.5
B6: 0.036933692 | C6: ENG | D6: Harry Brook | E6: Tarang | F6: 11 | I6: 10.5 | J6: 4 | K6: 6.5 | L6: 2.5 | M6: 11 | N6: 7 | O6: 6.5 | P6: 5.5
B7: 0.13844092 | C7: AUS | D7: Travis Head | E7: Shenoy | F7: 7.1 | I7: 3 | J7: 5 | K7: 8 | L7: 11.5 | M7: 9.5 | N7: 8.5 | O7: 5.5 | P7: 12.5
B8: 0.19470944 | C8: AUS | D8: Steve Smith © | E8: Tarang | F8: 10.5 | I8: 3 | J8: 16.5 | K8: 1.5 | L8: 1.5 | M8: 1.5 | N8: 6 | O8: 1 | P8: 14
B9: 0.30609745 | C9: NZ | D9: Will Young | E9: Devesh | F9: 5 | I9: 5 | J9: 2.5 | K9: 5 | L9: 1.5 | M9: 15.5 | N9: 1.5 | O9: 9.5 | P9: 7
A10: 2 | B10: 0.35004769 | C10: IND | D10: Rohit Sharma (c) | E10: Balajee | F10: 16.5 | I10: 1.6 | J10: 4.5 | K10: 13 | L10: 11 | M10: 6 | N10: 8.5 | O10: 4 | P10: 7.5
B11: 0.38493227 | C11: IND | D11: Virat Kohli | E11: Balajee | F11: 11.1 | I11: 8.5 | J11: 8.5 | K11: 13.5 | L11: 9 | M11: 2.5 | N11: 1.5 | O11: 3 | P11: 13
B12: 0.39187384 | C12: RSA | D12: David Miller | E12: Anand | F12: 10.5 | I12: 1 | J12: 6 | K12: 1.5 | L12: 2 | M12: 6 | N12: 14.5 | O12: 6.5 | P12: 3
B13: 0.42374765 | C13: AFG | D13: Sediqullah Atal | E13: Murthy | F13: 1.5 | I13: 4.5 | J13: 5 | K13: 4.5 | L13: 6 | M13: 11.5 | N13: 10.5 | O13: 1
B14: 0.4259506 | C14: AFG | D14: Hashmatullah Shahidi (c) | E14: Anand | F14: 3 | I14: 15.5 | J14: 3 | K14: 9 | L14: 12.5 | M14: 7.5 | N14: 9.5 | O14: 1.5
B15: 0.45289023 | C15: RSA | D15: Tony de Zorzi | E15: Anand | F15: 3 | I15: 21 | J15: 10 | K15: 7 | L15: 17.5 | M15: 2 | N15: 1 | O15: 4
B16: 0.46024854 | C16: AFG | D16: Ibrahim Zadran | E16: Anand | F16: 5 | I16: 1.5 | K16: 2.3 | L16: 9.5 | O16: 3.4
B17: 0.54903841 | C17: NZ | D17: Kane Williamson | E17: Devesh | F17: 15.2 | O17: 5
A18: 3 | B18: 0.58021802 | C18: IND | D18: Shubman Gill | E18: Murthy | F18: 15.2 | O18: 1
B19: 0.71050654 | C19: RSA | D19: Temba Bavuma (c) | E19: Devesh | F19: 7 | O19: 3.5
B20: 0.71563312 | C20: PAK | D20: Tayyab Tahir | E20: Shenoy | F20: 3.5 | O20: 3.5
B21: 0.72146586 | C21: IND | D21: Shreyas Iyer | E21: Gogu | F21: 17.5 | O21: 4
B22: 0.77393285 | C22: ENG | D22: Joe Root | E22: Murthy | F22: 14.5 | O22: 1
B23: 0.84818022 | C23: BAN | D23: Towhid Hridoy | E23: Maddy | F23: 2.5 | O23: 1
B24: 0.88569014 | C24: BAN | D24: Tanzid Hasan | E24: Anand | F24: 4.5 | O24: 2
B25: 0.94528039 | C25: AUS | D25: Matthew Short | E25: Balajee | F25: 6 | O25: 1
B26: 0.9687578 | C26: AUS | D26: Jake Fraser-McGurk | E26: Balajee | F26: 5 | O26: 2
C27: AUS | D27: Labuschagne | E27: Shenoy | F27: 3.5 | O27: 4.5
O28: 3.5
O29: 13
H31: Remaining Budget | I31: =I2-SUM(I3:I30) -> 2.9 | J31: =J2-SUM(J3:J30) -> 3.4 | K31: =K2-SUM(K3:K30) -> 0 | L31: =L2-SUM(L3:L30) -> 0 | M31: =M2-SUM(M3:M30) -> 1 | N31: =N2-SUM(N3:N30) -> 0.8 | O31: =O2-SUM(O3:O30) -> 0 | P31: =P2-SUM(P3:P30) -> 1

Sheet WK
A1: 1 | B1: Random | C1: Team | D1: Player | E1: Sold to | F1: Price (cr)
A2: 1 | B2: 0.097217028 | C2: NZ | D2: Tom Latham (wk) | E2: Tarang | F2: 5.5
B3: 0.12471327 | C3: AUS | D3: Josh Inglis (wk) | E3: Balajee | F3: 5
B4: 0.16485451 | C4: ENG | D4: Jos Buttler (c, wk) | E4: Devesh | F4: 13
B5: 0.21845877 | C5: ENG | D5: Jamie Smith (wk) | E5: Gogu | F5: 1.5
B6: 0.28847892 | C6: RSA | D6: Heinrich Klaasen | E6: Devesh | F6: 13.5
B7: 0.34962406 | C7: PAK | D7: Usman Khan | E7: Gogu | F7: 1.5
A8: 2 | B8: 0.40815579 | C8: AUS | D8: Alex Carey (wk) | E8: Murthy | F8: 8.5
B9: 0.46157613 | C9: ENG | D9: Phil Salt | E9: Tarang | F9: 15
B10: 0.59022425 | C10: IND | D10: Rishabh Pant | E10: Gogu | F10: 2
B11: 0.6414088 | C11: BAN | D11: Parvez Hossain Emon (wk) | E11: Shenoy | F11: 1
B12: 0.666394 | C12: AFG | D12: Rahmanullah Gurbaz (wk) | E12: Shenoy | F12: 4
B13: 0.69780889 | C13: PAK | D13: Mohammad Rizwan (c, wk) | E13: Maddy | F13: 15
B14: 0.73576829 | C14: RSA | D14: Ryan Rickelton | E14: Tarang | F14: 14
A15: 3 | B15: 0.74054322 | C15: BAN | D15: Mushfiqur Rahim (wk) | E15: Shenoy | F15: 4
B16: 0.79335962 | C16: NZ | D16: Devon Conway (wk) | E16: Anand | F16: 15.5
B17: 0.80975484 | C17: AFG | D17: Ikram Alikhil (wk) | E17: Devesh | F17: 2.3
B18: 0.87008667 | C18: RSA | D18: Tristan Stubbs | E18: Maddy | F18: 6
B19: 0.8828135 | C19: BAN | D19: Jaker Ali (wk) | E19: Shenoy | F19: 1
B20: 0.96397259 | C20: IND | D20: KL Rahul | E20: Maddy | F20: 11.5
C21: ENG | D21: Banton | E21: Shenoy | F21: 2

Sheet ML Model Points
A1: Name | B1: 45461 | C1: 45464 | D1: 45465 | E1: 45466 | F1: 45467
A2: Pranav | B2: 1905.25 | C2: 2250.75 | D2: 2717.25 | E2: 2722.25 | F2: 3035
A3: Varad | B3: 1939.75 | C3: 2143.5 | D3: 2495.25 | E3: 2568.25 | F3: 2898.5
A4: Tarang | B4: 2054.25 | C4: 2259 | D4: 2384.75 | E4: 2648.75 | F4: 2703.75
A5: Anand | B5: 2158.5 | C5: 2329.5 | D5: 2560.25 | E5: 2560.25 | F5: 2681.25
A6: Maddy | B6: 1877.75 | C6: 2058.75 | D6: 2174.75 | E6: 2330.75 | F6: 2590.5
A7: JD | B7: 1581.5 | C7: 2070.5 | D7: 2386.75 | E7: 2433.75 | F7: 2571.75
A8: Ankit | B8: 1528 | C8: 1739.25 | D8: 1866.75 | E8: 2057.25 | F8: 2426.75
A9: Herit | B9: 1722 | C9: 2019 | D9: 2201 | E9: 2322.75 | F9: 2407.25
A10: Devesh | B10: 1555 | C10: 2118.75 | D10: 2239.25 | E10: 2351.75 | F10: 2378.75
A11: Neil | B11: 1587 | C11: 1921 | D11: 2128 | E11: 2243 | F11: 2290
A12: Soham | B12: 1518 | C12: 1807.5 | D12: 1952.75 | E12: 2104.5 | F12: 2216.5
... A14: Murthy | B14: 1588.25 | C14: 1784.75 | D14: 1820.75 | E14: 2068 | F14: 2133
